[2023-09-15T11:47:23.059+0000] {taskinstance.py:1125} INFO - Dependencies all met for dep_context=non-requeueable deps ti=<TaskInstance: datamart_bisnis.daily_earnings scheduled__2023-09-14T02:00:00+00:00 [queued]>
[2023-09-15T11:47:23.071+0000] {taskinstance.py:1125} INFO - Dependencies all met for dep_context=requeueable deps ti=<TaskInstance: datamart_bisnis.daily_earnings scheduled__2023-09-14T02:00:00+00:00 [queued]>
[2023-09-15T11:47:23.072+0000] {taskinstance.py:1331} INFO - Starting attempt 2 of 2
[2023-09-15T11:47:23.088+0000] {taskinstance.py:1350} INFO - Executing <Task(PostgresOperator): daily_earnings> on 2023-09-14 02:00:00+00:00
[2023-09-15T11:47:23.099+0000] {standard_task_runner.py:57} INFO - Started process 151 to run task
[2023-09-15T11:47:23.104+0000] {standard_task_runner.py:84} INFO - Running: ['***', 'tasks', 'run', 'datamart_bisnis', 'daily_earnings', 'scheduled__2023-09-14T02:00:00+00:00', '--job-id', '33', '--raw', '--subdir', 'DAGS_FOLDER/datamart_bisnis.py', '--cfg-path', '/tmp/tmpm_hzx198']
[2023-09-15T11:47:23.107+0000] {standard_task_runner.py:85} INFO - Job 33: Subtask daily_earnings
[2023-09-15T11:47:23.193+0000] {task_command.py:410} INFO - Running <TaskInstance: datamart_bisnis.daily_earnings scheduled__2023-09-14T02:00:00+00:00 [running]> on host ecb76d2810ac
[2023-09-15T11:47:23.310+0000] {taskinstance.py:1570} INFO - Exporting env vars: AIRFLOW_CTX_DAG_OWNER='Imara Acacia' AIRFLOW_CTX_DAG_ID='datamart_bisnis' AIRFLOW_CTX_TASK_ID='daily_earnings' AIRFLOW_CTX_EXECUTION_DATE='2023-09-14T02:00:00+00:00' AIRFLOW_CTX_TRY_NUMBER='2' AIRFLOW_CTX_DAG_RUN_ID='scheduled__2023-09-14T02:00:00+00:00'
[2023-09-15T11:47:23.313+0000] {sql.py:262} INFO - Executing: 
    SELECT SUM("DailyEarnings") as "TotalEarning"
    FROM (
            SELECT "InvoiceDate", SUM("TotalPrice") as "DailyEarnings"
            FROM "artist_revenue"
            GROUP BY "InvoiceDate"
    ) as a
    
[2023-09-15T11:47:23.339+0000] {taskinstance.py:1847} ERROR - Task failed with exception
Traceback (most recent call last):
  File "/home/airflow/.local/lib/python3.7/site-packages/airflow/providers/common/sql/operators/sql.py", line 263, in execute
    hook = self.get_db_hook()
  File "/home/airflow/.local/lib/python3.7/site-packages/airflow/providers/common/sql/operators/sql.py", line 181, in get_db_hook
    return self._hook
  File "/home/airflow/.local/lib/python3.7/site-packages/cached_property.py", line 36, in __get__
    value = obj.__dict__[self.func.__name__] = self.func(obj)
  File "/home/airflow/.local/lib/python3.7/site-packages/airflow/providers/common/sql/operators/sql.py", line 143, in _hook
    conn = BaseHook.get_connection(self.conn_id)
  File "/home/airflow/.local/lib/python3.7/site-packages/airflow/hooks/base.py", line 72, in get_connection
    conn = Connection.get_connection_from_secrets(conn_id)
  File "/home/airflow/.local/lib/python3.7/site-packages/airflow/models/connection.py", line 434, in get_connection_from_secrets
    raise AirflowNotFoundException(f"The conn_id `{conn_id}` isn't defined")
airflow.exceptions.AirflowNotFoundException: The conn_id `datawarehouse` isn't defined
[2023-09-15T11:47:23.346+0000] {taskinstance.py:1373} INFO - Marking task as FAILED. dag_id=datamart_bisnis, task_id=daily_earnings, execution_date=20230914T020000, start_date=20230915T114723, end_date=20230915T114723
[2023-09-15T11:47:23.363+0000] {standard_task_runner.py:109} ERROR - Failed to execute job 33 for task daily_earnings (The conn_id `datawarehouse` isn't defined; 151)
[2023-09-15T11:47:23.396+0000] {local_task_job_runner.py:232} INFO - Task exited with return code 1
[2023-09-15T11:47:23.427+0000] {taskinstance.py:2674} INFO - 0 downstream tasks scheduled from follow-on schedule check
