[2023-09-15T11:47:28.285+0000] {taskinstance.py:1125} INFO - Dependencies all met for dep_context=non-requeueable deps ti=<TaskInstance: datamart_bisnis.daily_earnings manual__2023-09-14T17:35:32.434503+00:00 [queued]>
[2023-09-15T11:47:28.303+0000] {taskinstance.py:1125} INFO - Dependencies all met for dep_context=requeueable deps ti=<TaskInstance: datamart_bisnis.daily_earnings manual__2023-09-14T17:35:32.434503+00:00 [queued]>
[2023-09-15T11:47:28.304+0000] {taskinstance.py:1331} INFO - Starting attempt 2 of 2
[2023-09-15T11:47:28.340+0000] {taskinstance.py:1350} INFO - Executing <Task(PostgresOperator): daily_earnings> on 2023-09-14 17:35:32.434503+00:00
[2023-09-15T11:47:28.347+0000] {standard_task_runner.py:57} INFO - Started process 154 to run task
[2023-09-15T11:47:28.361+0000] {standard_task_runner.py:84} INFO - Running: ['***', 'tasks', 'run', 'datamart_bisnis', 'daily_earnings', 'manual__2023-09-14T17:35:32.434503+00:00', '--job-id', '34', '--raw', '--subdir', 'DAGS_FOLDER/datamart_bisnis.py', '--cfg-path', '/tmp/tmpcg_w92ws']
[2023-09-15T11:47:28.377+0000] {standard_task_runner.py:85} INFO - Job 34: Subtask daily_earnings
[2023-09-15T11:47:28.516+0000] {task_command.py:410} INFO - Running <TaskInstance: datamart_bisnis.daily_earnings manual__2023-09-14T17:35:32.434503+00:00 [running]> on host ecb76d2810ac
[2023-09-15T11:47:28.676+0000] {taskinstance.py:1570} INFO - Exporting env vars: AIRFLOW_CTX_DAG_OWNER='Imara Acacia' AIRFLOW_CTX_DAG_ID='datamart_bisnis' AIRFLOW_CTX_TASK_ID='daily_earnings' AIRFLOW_CTX_EXECUTION_DATE='2023-09-14T17:35:32.434503+00:00' AIRFLOW_CTX_TRY_NUMBER='2' AIRFLOW_CTX_DAG_RUN_ID='manual__2023-09-14T17:35:32.434503+00:00'
[2023-09-15T11:47:28.680+0000] {sql.py:262} INFO - Executing: 
    SELECT SUM("DailyEarnings") as "TotalEarning"
    FROM (
            SELECT "InvoiceDate", SUM("TotalPrice") as "DailyEarnings"
            FROM "artist_revenue"
            GROUP BY "InvoiceDate"
    ) as a
    
[2023-09-15T11:47:28.868+0000] {taskinstance.py:1847} ERROR - Task failed with exception
Traceback (most recent call last):
  File "/home/airflow/.local/lib/python3.7/site-packages/airflow/providers/common/sql/operators/sql.py", line 263, in execute
    hook = self.get_db_hook()
  File "/home/airflow/.local/lib/python3.7/site-packages/airflow/providers/common/sql/operators/sql.py", line 181, in get_db_hook
    return self._hook
  File "/home/airflow/.local/lib/python3.7/site-packages/cached_property.py", line 36, in __get__
    value = obj.__dict__[self.func.__name__] = self.func(obj)
  File "/home/airflow/.local/lib/python3.7/site-packages/airflow/providers/common/sql/operators/sql.py", line 143, in _hook
    conn = BaseHook.get_connection(self.conn_id)
  File "/home/airflow/.local/lib/python3.7/site-packages/airflow/hooks/base.py", line 72, in get_connection
    conn = Connection.get_connection_from_secrets(conn_id)
  File "/home/airflow/.local/lib/python3.7/site-packages/airflow/models/connection.py", line 434, in get_connection_from_secrets
    raise AirflowNotFoundException(f"The conn_id `{conn_id}` isn't defined")
airflow.exceptions.AirflowNotFoundException: The conn_id `datawarehouse` isn't defined
[2023-09-15T11:47:28.883+0000] {taskinstance.py:1373} INFO - Marking task as FAILED. dag_id=datamart_bisnis, task_id=daily_earnings, execution_date=20230914T173532, start_date=20230915T114728, end_date=20230915T114728
[2023-09-15T11:47:28.914+0000] {standard_task_runner.py:109} ERROR - Failed to execute job 34 for task daily_earnings (The conn_id `datawarehouse` isn't defined; 154)
[2023-09-15T11:47:28.966+0000] {local_task_job_runner.py:232} INFO - Task exited with return code 1
[2023-09-15T11:47:29.010+0000] {taskinstance.py:2674} INFO - 0 downstream tasks scheduled from follow-on schedule check
